Workbook

Sheet Phòng thuốc 03_2026
A1: STT | B1: Tháng | C1: Phòng | D1: Họ và tên đầy đủ | E1: Inside | F1: Mail FPT | G1: Leader | H1: Team | I1: Total points | J1: Đánh giá
A2: =ROW()-1 -> 1 | B2: 3 | C2: Thuốc | D2: Tống Bích Ngọc | E2: 42670 | F2: ngoctb21@fpt.com | G2: Tống Bích Ngọc | H2: Tick | I2: 7.5 | J2: =IF(I2>=8,"Giỏi",IF(I2>=6.5,"Khá",IF(I2>=4.5,"Trung bình","Yếu"))) -> Khá
A3: =ROW()-1 -> 2 | B3: 3 | C3: Thuốc | D3: Nguyễn Đăng Dương | E3: 59649 | F3: DuongND46@fpt.com | G3: Cù Thị Thu | H3: Chat | I3: 6 | J3: =IF(I3>=8,"Giỏi",IF(I3>=6.5,"Khá",IF(I3>=4.5,"Trung bình","Yếu"))) -> Trung bình | M3: 📊 Tổng hợp đánh giá Tháng 03
A4: =ROW()-1 -> 3 | B4: 3 | C4: Thuốc | D4: Nông Thị Tuyên | E4: 42816 | F4: TuyenNT44@fpt.com | G4: Nông Thị Tuyên | H4: Tick | I4: 7.5 | J4: =IF(I4>=8,"Giỏi",IF(I4>=6.5,"Khá",IF(I4>=4.5,"Trung bình","Yếu"))) -> Khá
A5: =ROW()-1 -> 4 | B5: 3 | C5: Thuốc | D5: Nguyễn Thị Mai Hương | E5: 53486 | F5: Huongntm20@fpt.com | G5: Nguyễn Thị Khánh | H5: Call | I5: 8.5 | J5: =IF(I5>=8,"Giỏi",IF(I5>=6.5,"Khá",IF(I5>=4.5,"Trung bình","Yếu"))) -> Giỏi | M5: Tiêu chí | N5: Số lượng | O5: Tỷ lệ | R5: Team | S5: Giỏi | T5: Khá | U5: Trung bình | V5: Yếu | W5: Grand Total
A6: =ROW()-1 -> 5 | B6: 3 | C6: Thuốc | D6: Nguyễn Mạnh Kiên | E6: 47583 | F6: KienNM5@fpt.com | G6: Nguyễn Thị Khánh | H6: Call | I6: 7 | J6: =IF(I6>=8,"Giỏi",IF(I6>=6.5,"Khá",IF(I6>=4.5,"Trung bình","Yếu"))) -> Khá | M6: Giỏi | N6: =S10 -> 73 | O6: =S10/W10 -> 0.42196532 | R6: Chat | S6: =COUNTIFS('Phòng thuốc 03_2026'!$H:$H,"Chat", 'Phòng thuốc 03_2026'!$J:$J, "Giỏi") -> 25 | T6: =COUNTIFS('Phòng thuốc 03_2026'!$H:$H,"Chat", 'Phòng thuốc 03_2026'!$J:$J, "Khá") -> 28 | U6: =COUNTIFS('Phòng thuốc 03_2026'!$H:$H,"Chat", 'Phòng thuốc 03_2026'!$J:$J, "Trung bình") -> 10 | V6: =COUNTIFS('Phòng thuốc 03_2026'!$H:$H,"Chat", 'Phòng thuốc 03_2026'!$J:$J, "Yếu") -> 0 | W6: =SUM(S6:V6) -> 63
A7: =ROW()-1 -> 6 | B7: 3 | C7: Thuốc | D7: Nguyễn Ngọc Thanh Ngân | E7: 63390 | F7: NganNNT10@fpt.com | G7: Kim Ánh Ngọc | H7: Chat | I7: 7.5 | J7: =IF(I7>=8,"Giỏi",IF(I7>=6.5,"Khá",IF(I7>=4.5,"Trung bình","Yếu"))) -> Khá | M7: Khá | N7: =T10 -> 75 | O7: =T10/W10 -> 0.43352601 | R7: Call | S7: =COUNTIFS('Phòng thuốc 03_2026'!$H:$H,"Call", 'Phòng thuốc 03_2026'!$J:$J, "Giỏi") -> 33 | T7: =COUNTIFS('Phòng thuốc 03_2026'!$H:$H,"Call", 'Phòng thuốc 03_2026'!$J:$J, "Khá") -> 20 | U7: =COUNTIFS('Phòng thuốc 03_2026'!$H:$H,"Call", 'Phòng thuốc 03_2026'!$J:$J, "Trung bình") -> 3 | V7: =COUNTIFS('Phòng thuốc 03_2026'!$H:$H,"Call", 'Phòng thuốc 03_2026'!$J:$J, "Yếu") -> 1 | W7: =SUM(S7:V7) -> 57
A8: =ROW()-1 -> 7 | B8: 3 | C8: Thuốc | D8: Nguyễn Hoàng Minh Hiếu | E8: 7788 | F8: HieuNHM3@fpt.com | G8: Nguyễn Hoàng Minh Hiếu | H8: Call | I8: 8.5 | J8: =IF(I8>=8,"Giỏi",IF(I8>=6.5,"Khá",IF(I8>=4.5,"Trung bình","Yếu"))) -> Giỏi | M8: Trung bình | N8: =U10 -> 24 | O8: =N8/W10 -> 0.13872832 | R8: Tick | S8: =COUNTIFS('Phòng thuốc 03_2026'!H:H,"Tick", 'Phòng thuốc 03_2026'!J:J, "Giỏi") -> 9 | T8: =COUNTIFS('Phòng thuốc 03_2026'!$H:$H,"Tick", 'Phòng thuốc 03_2026'!$J:$J, "Khá") -> 18 | U8: =COUNTIFS('Phòng thuốc 03_2026'!$H:$H,"Tick", 'Phòng thuốc 03_2026'!$J:$J, "Trung bình") -> 10 | V8: =COUNTIFS('Phòng thuốc 03_2026'!$H:$H,"Tick", 'Phòng thuốc 03_2026'!$J:$J, "Yếu") -> 0 | W8: =SUM(S8:V8) -> 37
A9: =ROW()-1 -> 8 | B9: 3 | C9: Thuốc | D9: Nguyễn Ngọc Quỳnh Như | E9: 68073 | F9: Nhunnq5@fpt.com | G9: Nguyễn Hoàng Minh Hiếu | H9: Call | I9: 8 | J9: =IF(I9>=8,"Giỏi",IF(I9>=6.5,"Khá",IF(I9>=4.5,"Trung bình","Yếu"))) -> Giỏi | M9: Yếu | N9: =V10 -> 1 | O9: =V10/W10 -> 0.0057803468 | R9: CMYD | S9: =COUNTIFS('Phòng thuốc 03_2026'!H:H,"CMYD", 'Phòng thuốc 03_2026'!J:J, "Giỏi") -> 6 | T9: =COUNTIFS('Phòng thuốc 03_2026'!$H:$H,"CMYD", 'Phòng thuốc 03_2026'!$J:$J, "Khá") -> 9 | U9: =COUNTIFS('Phòng thuốc 03_2026'!$H:$H,"CMYD", 'Phòng thuốc 03_2026'!$J:$J, "Trung bình") -> 1 | V9: =COUNTIFS('Phòng thuốc 03_2026'!$H:$H,"CMYD", 'Phòng thuốc 03_2026'!$J:$J, "Yếu") -> 0 | W9: =SUM(S9:V9) -> 16
A10: =ROW()-1 -> 9 | B10: 3 | C10: Thuốc | D10: Hoàng Lan Nhi | E10: 54438 | F10: NhiHL@fpt.com | G10: Nguyễn Hoàng Minh Hiếu | H10: Call | I10: 7.5 | J10: =IF(I10>=8,"Giỏi",IF(I10>=6.5,"Khá",IF(I10>=4.5,"Trung bình","Yếu"))) -> Khá | M10: Tổng | N10: =W10 -> 173 | O10: =SUM(O6:O9) -> 1 | R10: Grand Total | S10: =SUM(S6:S9) -> 73 | T10: =SUM(T6:T9) -> 75 | U10: =SUM(U6:U9) -> 24 | V10: =SUM(V6:V9) -> 1 | W10: =SUM(S10:V10) -> 173
A11: =ROW()-1 -> 10 | B11: 3 | C11: Thuốc | D11: Trần Thị Phương Chi | E11: ChiTTP5 | F11: ChiTTP5@fpt.com | G11: Tống Bích Ngọc | H11: Tick | I11: 7 | J11: =IF(I11>=8,"Giỏi",IF(I11>=6.5,"Khá",IF(I11>=4.5,"Trung bình","Yếu"))) -> Khá
A12: =ROW()-1 -> 11 | B12: 3 | C12: Thuốc | D12: Nguyễn Bích Diệp | E12: 50158 | F12: Diepnb6@fpt.com | G12: Kim Ánh Ngọc | H12: Chat | I12: 6 | J12: =IF(I12>=8,"Giỏi",IF(I12>=6.5,"Khá",IF(I12>=4.5,"Trung bình","Yếu"))) -> Trung bình
A13: =ROW()-1 -> 12 | B13: 3 | C13: Thuốc | D13: Trần Thị Sen | E13: 59074 | F13: sentt5@fpt.com | G13: Võ Hải Hưng | H13: Call | I13: 6 | J13: =IF(I13>=8,"Giỏi",IF(I13>=6.5,"Khá",IF(I13>=4.5,"Trung bình","Yếu"))) -> Trung bình | R13: Team | S13: Giỏi | T13: Khá | U13: Trung bình | V13: Yếu
A14: =ROW()-1 -> 13 | B14: 3 | C14: Thuốc | D14: Phan Ngọc Diệu | E14: 47831 | F14: DieuPTN2@fpt.com | G14: Cù Thị Thu | H14: Chat | I14: 6 | J14: =IF(I14>=8,"Giỏi",IF(I14>=6.5,"Khá",IF(I14>=4.5,"Trung bình","Yếu"))) -> Trung bình | R14: Chat | S14: =S6/W6 -> 0.3968254 | T14: =T6/W6 -> 0.44444444 | U14: =U6/W6 -> 0.15873016 | V14: =V6/W6 -> 0
A15: =ROW()-1 -> 14 | B15: 3 | C15: Thuốc | D15: Nguyễn Thị Thanh Vân | E15: 63392 | F15: VanNTT65 | G15: Tống Bích Ngọc | H15: Tick | I15: 5.5 | J15: =IF(I15>=8,"Giỏi",IF(I15>=6.5,"Khá",IF(I15>=4.5,"Trung bình","Yếu"))) -> Trung bình | R15: Call | S15: =S7/W7 -> 0.57894737 | T15: =T7/W7 -> 0.35087719 | U15: =U7/W7 -> 0.052631579 | V15: =V7/W7 -> 0.01754386
A16: =ROW()-1 -> 15 | B16: 3 | C16: Thuốc | D16: Tạ Thu Hà | E16: 59650 | F16: HaTT59@fpt.com | G16: Tống Bích Ngọc | H16: Tick | I16: 8 | J16: =IF(I16>=8,"Giỏi",IF(I16>=6.5,"Khá",IF(I16>=4.5,"Trung bình","Yếu"))) -> Giỏi | R16: Tick | S16: =S8/W8 -> 0.24324324 | T16: =T8/W8 -> 0.48648649 | U16: =U8/W8 -> 0.27027027 | V16: =V8/W8 -> 0
A17: =ROW()-1 -> 16 | B17: 3 | C17: Thuốc | D17: Nguyễn Phương Lan | E17: 48677 | F17: lannp9@fpt.com | G17: Trương Thị Trang | H17: Chat | I17: 7.5 | J17: =IF(I17>=8,"Giỏi",IF(I17>=6.5,"Khá",IF(I17>=4.5,"Trung bình","Yếu"))) -> Khá | R17: CMYD | S17: =S9/W9 -> 0.375 | T17: =T9/W9 -> 0.5625 | U17: =U9/W9 -> 0.0625 | V17: =V9/W9 -> 0
A18: =ROW()-1 -> 17 | B18: 3 | C18: Thuốc | D18: Lê Anh | E18: 50156 | F18: anhl4@fpt.com | G18: Tống Bích Ngọc | H18: Tick | I18: 8 | J18: =IF(I18>=8,"Giỏi",IF(I18>=6.5,"Khá",IF(I18>=4.5,"Trung bình","Yếu"))) -> Giỏi
A19: =ROW()-1 -> 18 | B19: 3 | C19: Thuốc | D19: Kim Ánh Ngọc | E19: 45696 | F19: NgocKA@fpt.com | G19: Kim Ánh Ngọc | H19: Chat | I19: 8.5 | J19: =IF(I19>=8,"Giỏi",IF(I19>=6.5,"Khá",IF(I19>=4.5,"Trung bình","Yếu"))) -> Giỏi
A20: =ROW()-1 -> 19 | B20: 3 | C20: Thuốc | D20: Trương Thị Hằng | E20: 66569 | F20: HangTT88@fpt.com | G20: Cù Thị Thu | H20: Chat | I20: 5.5 | J20: =IF(I20>=8,"Giỏi",IF(I20>=6.5,"Khá",IF(I20>=4.5,"Trung bình","Yếu"))) -> Trung bình
A21: =ROW()-1 -> 20 | B21: 3 | C21: Thuốc | D21: Mai Huỳnh Khánh Uyên | E21: 7801 | F21: UyenMHK @fpt.com | G21: Vũ Lê Như Uyên | H21: CMYD | I21: 7 | J21: =IF(I21>=8,"Giỏi",IF(I21>=6.5,"Khá",IF(I21>=4.5,"Trung bình","Yếu"))) -> Khá
A22: =ROW()-1 -> 21 | B22: 3 | C22: Thuốc | D22: Võ Thị Cẩm Nhung | E22: 66662 | F22: NhungVTC3@fpt.com | G22: Võ Hải Hưng | H22: Call | I22: 6.5 | J22: =IF(I22>=8,"Giỏi",IF(I22>=6.5,"Khá",IF(I22>=4.5,"Trung bình","Yếu"))) -> Khá
A23: =ROW()-1 -> 22 | B23: 3 | C23: Thuốc | D23: Nguyễn Thị Ánh Hồng | E23: 63106 | F23: HongNTA5@fpt.com | G23: Nông Thị Tuyên | H23: Tick | I23: 6 | J23: =IF(I23>=8,"Giỏi",IF(I23>=6.5,"Khá",IF(I23>=4.5,"Trung bình","Yếu"))) -> Trung bình
A24: =ROW()-1 -> 23 | B24: 3 | C24: Thuốc | D24: Nguyễn Văn Anh | E24: 45174 | F24: anhnv103@fpt.com | G24: Nguyễn Văn Anh | H24: Call | I24: 8 | J24: =IF(I24>=8,"Giỏi",IF(I24>=6.5,"Khá",IF(I24>=4.5,"Trung bình","Yếu"))) -> Giỏi
A25: =ROW()-1 -> 24 | B25: 3 | C25: Thuốc | D25: Lê Thị Lệ Hằng | E25: 6165 | F25: HangLTL2@fpt.com | G25: Nguyễn Hoàng Minh Hiếu | H25: Call | I25: 8 | J25: =IF(I25>=8,"Giỏi",IF(I25>=6.5,"Khá",IF(I25>=4.5,"Trung bình","Yếu"))) -> Giỏi | O25: =173*9 -> 1557
A26: =ROW()-1 -> 25 | B26: 3 | C26: Thuốc | D26: Trương Ngọc Anh | E26: 54516 | F26: AnhTN28@fpt.com | G26: Kiều Thùy Linh | H26: Call | I26: 7 | J26: =IF(I26>=8,"Giỏi",IF(I26>=6.5,"Khá",IF(I26>=4.5,"Trung bình","Yếu"))) -> Khá
A27: =ROW()-1 -> 26 | B27: 3 | C27: Thuốc | D27: Nguyễn Tuấn Đại | E27: 54947 | F27: daint17@fpt.com | G27: Đặng Thu Hà | H27: CMYD | I27: 7 | J27: =IF(I27>=8,"Giỏi",IF(I27>=6.5,"Khá",IF(I27>=4.5,"Trung bình","Yếu"))) -> Khá
A28: =ROW()-1 -> 27 | B28: 3 | C28: Thuốc | D28: mai đoàn anh thư | E28: 50926 | F28: thumda@fpt..com | G28: Vũ Lê Như Uyên | H28: CMYD | I28: 7 | J28: =IF(I28>=8,"Giỏi",IF(I28>=6.5,"Khá",IF(I28>=4.5,"Trung bình","Yếu"))) -> Khá
A29: =ROW()-1 -> 28 | B29: 3 | C29: Thuốc | D29: Nguyễn Thị Khánh | E29: 42376 | F29: KhanhNT30@fpt.com | G29: Nguyễn Thị Khánh | H29: Call | I29: 9 | J29: =IF(I29>=8,"Giỏi",IF(I29>=6.5,"Khá",IF(I29>=4.5,"Trung bình","Yếu"))) -> Giỏi
A30: =ROW()-1 -> 29 | B30: 3 | C30: Thuốc | D30: Nguyễn Thị Cần | E30: 54517 | F30: CanNT2 | G30: Kiều Thùy Linh | H30: Call | I30: 7 | J30: =IF(I30>=8,"Giỏi",IF(I30>=6.5,"Khá",IF(I30>=4.5,"Trung bình","Yếu"))) -> Khá
A31: =ROW()-1 -> 30 | B31: 3 | C31: Thuốc | D31: nguyễn thị phương vân | E31: 63103 | F31: vanntp@fpt.com | G31: Đặng Thu Hà | H31: CMYD | I31: 7 | J31: =IF(I31>=8,"Giỏi",IF(I31>=6.5,"Khá",IF(I31>=4.5,"Trung bình","Yếu"))) -> Khá
A32: =ROW()-1 -> 31 | B32: 3 | C32: Thuốc | D32: Mai Thị Thanh Trà | E32: 57710 | F32: TraMTT10@fpt.com | G32: Kim Ánh Ngọc | H32: Chat | I32: 5 | J32: =IF(I32>=8,"Giỏi",IF(I32>=6.5,"Khá",IF(I32>=4.5,"Trung bình","Yếu"))) -> Trung bình
A33: =ROW()-1 -> 32 | B33: 3 | C33: Thuốc | D33: Hà Phương Thảo | E33: 56559 | F33: Thaohp12@fpt.com | G33: Nguyễn Văn Anh | H33: Call | I33: 8 | J33: =IF(I33>=8,"Giỏi",IF(I33>=6.5,"Khá",IF(I33>=4.5,"Trung bình","Yếu"))) -> Giỏi
A34: =ROW()-1 -> 33 | B34: 3 | C34: Thuốc | D34: Lê Thị Mai Anh | E34: 55240 | F34: AnhLTM9@fpt.com | G34: Cù Thị Thu | H34: Chat | I34: 8.5 | J34: =IF(I34>=8,"Giỏi",IF(I34>=6.5,"Khá",IF(I34>=4.5,"Trung bình","Yếu"))) -> Giỏi
A35: =ROW()-1 -> 34 | B35: 3 | C35: Thuốc | D35: Chu Thị Quỳnh | E35: 58972 | F35: quynhct2@fpt.com | G35: Đặng Thu Hà | H35: CMYD | I35: 7 | J35: =IF(I35>=8,"Giỏi",IF(I35>=6.5,"Khá",IF(I35>=4.5,"Trung bình","Yếu"))) -> Khá
A36: =ROW()-1 -> 35 | B36: 3 | C36: Thuốc | D36: Nguyễn Trần Kim Kha | E36: 47749 | F36: Khantk4@fpt.com | G36: Nguyễn Trần Kim Kha | H36: Call | I36: 7.5 | J36: =IF(I36>=8,"Giỏi",IF(I36>=6.5,"Khá",IF(I36>=4.5,"Trung bình","Yếu"))) -> Khá
A37: =ROW()-1 -> 36 | B37: 3 | C37: Thuốc | D37: Nguyễn Thanh Tâm | E37: 41176 | F37: TamNT124@fpt.com | G37: Nguyễn Thanh Tâm | H37: Call | I37: 8 | J37: =IF(I37>=8,"Giỏi",IF(I37>=6.5,"Khá",IF(I37>=4.5,"Trung bình","Yếu"))) -> Giỏi
... A137: =ROW()-1 -> 136 | B137: 3 | C137: Thuốc | D137: Trần Bảo Quyên | E137: 68492 | F137: QuyenTB6@fpt.com | G137: Huỳnh Quang Đức | H137: Chat | I137: 5 | J137: =IF(I137>=8,"Giỏi",IF(I137>=6.5,"Khá",IF(I137>=4.5,"Trung bình","Yếu"))) -> Trung bình
A138: =ROW()-1 -> 137 | B138: 3 | C138: Thuốc | D138: Vũ Tiến Thành | E138: ThanhVT57 | F138: ThanhVT57@fpt.com | G138: Kim Ánh Ngọc | H138: Chat | I138: 8 | J138: =IF(I138>=8,"Giỏi",IF(I138>=6.5,"Khá",IF(I138>=4.5,"Trung bình","Yếu"))) -> Giỏi
A139: =ROW()-1 -> 138 | B139: 3 | C139: Thuốc | D139: Nguyễn Hoàng Kim Ngân | E139: 63996 | F139: ngannhk4 | G139: Lê Thị Thảo Loan | H139: Chat | I139: 7 | J139: =IF(I139>=8,"Giỏi",IF(I139>=6.5,"Khá",IF(I139>=4.5,"Trung bình","Yếu"))) -> Khá
...
